Workbook

Sheet Dashboard
A1: 50/30/20 DASHBOARD
A3: WHICH MONTH DO YOU WANT TO IMPROVE?
H4: SELECT MONTH → | I4: January
A6: SOURCE | C6: BUDGET | E6: REAL | I6: =MATCH(I4,Reference!$G$1:$G$12,0)
A7: INCOME | C7: ='Budget Setup'!B2 | E7: ='Budget Setup'!B2
A8: BILLS | C8: =IFERROR(SUMIFS('Budget Setup'!E:E,'Budget Setup'!F:F,"Bills"),0) | E8: =IFERROR(SUMIFS(Transactions!B:B,Transactions!D:D,"Bills",MONTH(Transactions!A:A),I$6),0)
A9: SUBSCRIPTIONS | C9: =IFERROR(SUMIFS('Budget Setup'!E:E,'Budget Setup'!F:F,"Subscriptions"),0) | E9: =IFERROR(SUMIFS(Transactions!B:B,Transactions!D:D,"Subscriptions",MONTH(Transactions!A:A),I$6),0)
A10: EXPENSES | C10: =IFERROR('Budget Setup'!B2*('Budget Setup'!B3/100)-C8-C9,0) | E10: =IFERROR(SUMIFS(Transactions!B:B,Transactions!D:D,"Expenses",MONTH(Transactions!A:A),I$6),0)
A11: SAVINGS | C11: =IFERROR('Budget Setup'!B2*('Budget Setup'!B5/100)*0.5,0) | E11: =IFERROR(SUMIFS(Transactions!B:B,Transactions!D:D,"Savings",MONTH(Transactions!A:A),I$6),0)
A12: DEBTS | C12: =IFERROR('Budget Setup'!B2*('Budget Setup'!B5/100)*0.5,0) | E12: =IFERROR(SUMIFS(Transactions!B:B,Transactions!D:D,"Debts",MONTH(Transactions!A:A),I$6),0)
A13: AMOUNT LEFT | E13: =IFERROR(E7-SUM(E8:E12),0)
A15: MY GOAL BREAKDOWN
A16: CATEGORY | C16: % | E16: $
A17: Need | C17: =TEXT('Budget Setup'!B3/100,"0%") | E17: ='Budget Setup'!B2*('Budget Setup'!B3/100)
A18: Want | C18: =TEXT('Budget Setup'!B4/100,"0%") | E18: ='Budget Setup'!B2*('Budget Setup'!B4/100)
A19: Savings / Debts | C19: =TEXT('Budget Setup'!B5/100,"0%") | E19: ='Budget Setup'!B2*('Budget Setup'!B5/100)
A20: TOTAL | C20: 100% | E20: =SUM(E17:E19)
A22: MY REAL BUDGET BREAKDOWN
A23: CATEGORY | C23: % | E23: $
A24: Need | C24: =IFERROR(E24/E7,0) | E24: =IFERROR(SUMIFS(Transactions!B:B,Transactions!F:F,"Need",MONTH(Transactions!A:A),I$6),0)
A25: Want | C25: =IFERROR(E25/E7,0) | E25: =IFERROR(SUMIFS(Transactions!B:B,Transactions!F:F,"Want",MONTH(Transactions!A:A),I$6),0)
A26: Savings / Debts | C26: =IFERROR(E26/E7,0) | E26: =IFERROR(SUMIFS(Transactions!B:B,Transactions!F:F,"Savings / Debts",MONTH(Transactions!A:A),I$6),0)
A27: TOTAL | C27: =IFERROR(SUM(C24:C26),0) | E27: =SUM(E24:E26)
A29: TRANSACTION TRACKER
A30: DATE | B30: AMOUNT | C30: SUB-CATEGORY | D30: CATEGORY | E30: DESCRIPTION | F30: BUCKET
A31: =IFERROR(QUERY(Transactions!A:F,"SELECT A,B,C,D,E,F WHERE A IS NOT NULL AND MONTH(A)+1 = "&I$6&" ORDER BY A DESC LABEL A '',B '',C '',D '',E '',F ''"),"")

Sheet Transactions
A1: DATE | B1: AMOUNT | C1: SUB-CATEGORY | D1: CATEGORY | E1: DESCRIPTION | F1: BUCKET
A2: 45292 | B2: 1200 | C2: Rent/Mortgage | D2: =IFERROR(VLOOKUP(C2,Reference!$A:$B,2,0),"") | E2: Monthly rent | F2: =IFERROR(VLOOKUP(C2,Reference!$D:$E,2,0),"")
A3: 45292 | B3: 80 | C3: Utilities | D3: =IFERROR(VLOOKUP(C3,Reference!$A:$B,2,0),"") | E3: Electric bill | F3: =IFERROR(VLOOKUP(C3,Reference!$D:$E,2,0),"")
A4: 45293 | B4: 100 | C4: Groceries | D4: =IFERROR(VLOOKUP(C4,Reference!$A:$B,2,0),"") | E4: Weekly shop | F4: =IFERROR(VLOOKUP(C4,Reference!$D:$E,2,0),"")
A5: 45294 | B5: 45 | C5: Internet | D5: =IFERROR(VLOOKUP(C5,Reference!$A:$B,2,0),"") | F5: =IFERROR(VLOOKUP(C5,Reference!$D:$E,2,0),"")
A6: 45295 | B6: 55 | C6: Phone | D6: =IFERROR(VLOOKUP(C6,Reference!$A:$B,2,0),"") | F6: =IFERROR(VLOOKUP(C6,Reference!$D:$E,2,0),"")
A7: 45296 | B7: 500 | C7: Loan Payment | D7: =IFERROR(VLOOKUP(C7,Reference!$A:$B,2,0),"") | E7: Car loan | F7: =IFERROR(VLOOKUP(C7,Reference!$D:$E,2,0),"")
A8: 45296 | B8: 60 | C8: Gym | D8: =IFERROR(VLOOKUP(C8,Reference!$A:$B,2,0),"") | F8: =IFERROR(VLOOKUP(C8,Reference!$D:$E,2,0),"")
A9: 45297 | B9: 45 | C9: Streaming | D9: =IFERROR(VLOOKUP(C9,Reference!$A:$B,2,0),"") | E9: Netflix + Spotify | F9: =IFERROR(VLOOKUP(C9,Reference!$D:$E,2,0),"")
A10: 45298 | B10: 150 | C10: Groceries | D10: =IFERROR(VLOOKUP(C10,Reference!$A:$B,2,0),"") | F10: =IFERROR(VLOOKUP(C10,Reference!$D:$E,2,0),"")
A11: 45299 | B11: 90 | C11: Dining Out | D11: =IFERROR(VLOOKUP(C11,Reference!$A:$B,2,0),"") | E11: Birthday dinner | F11: =IFERROR(VLOOKUP(C11,Reference!$D:$E,2,0),"")
A12: 45301 | B12: 200 | C12: Clothes | D12: =IFERROR(VLOOKUP(C12,Reference!$A:$B,2,0),"") | E12: Winter jacket | F12: =IFERROR(VLOOKUP(C12,Reference!$D:$E,2,0),"")
A13: 45303 | B13: 120 | C13: Gas | D13: =IFERROR(VLOOKUP(C13,Reference!$A:$B,2,0),"") | F13: =IFERROR(VLOOKUP(C13,Reference!$D:$E,2,0),"")
A14: 45305 | B14: 75 | C14: Drugstore | D14: =IFERROR(VLOOKUP(C14,Reference!$A:$B,2,0),"") | F14: =IFERROR(VLOOKUP(C14,Reference!$D:$E,2,0),"")
A15: 45306 | B15: 250 | C15: Savings Transfer | D15: =IFERROR(VLOOKUP(C15,Reference!$A:$B,2,0),"") | E15: Monthly savings | F15: =IFERROR(VLOOKUP(C15,Reference!$D:$E,2,0),"")
A16: 45307 | B16: 40 | C16: Entertainment | D16: =IFERROR(VLOOKUP(C16,Reference!$A:$B,2,0),"") | E16: Cinema | F16: =IFERROR(VLOOKUP(C16,Reference!$D:$E,2,0),"")
A17: 45309 | B17: 500 | C17: Other | D17: =IFERROR(VLOOKUP(C17,Reference!$A:$B,2,0),"") | E17: Boat repair | F17: =IFERROR(VLOOKUP(C17,Reference!$D:$E,2,0),"")
A18: 45311 | B18: 150 | C18: Health | D18: =IFERROR(VLOOKUP(C18,Reference!$A:$B,2,0),"") | E18: Dentist | F18: =IFERROR(VLOOKUP(C18,Reference!$D:$E,2,0),"")
A19: 45313 | B19: 50 | C19: Transport | D19: =IFERROR(VLOOKUP(C19,Reference!$A:$B,2,0),"") | E19: Uber rides | F19: =IFERROR(VLOOKUP(C19,Reference!$D:$E,2,0),"")
A20: 45316 | B20: 130 | C20: Dining Out | D20: =IFERROR(VLOOKUP(C20,Reference!$A:$B,2,0),"") | F20: =IFERROR(VLOOKUP(C20,Reference!$D:$E,2,0),"")
A21: 45319 | B21: 15 | C21: Clothes | D21: =IFERROR(VLOOKUP(C21,Reference!$A:$B,2,0),"") | F21: =IFERROR(VLOOKUP(C21,Reference!$D:$E,2,0),"")
A22: 45323 | B22: 1200 | C22: Rent/Mortgage | D22: =IFERROR(VLOOKUP(C22,Reference!$A:$B,2,0),"") | F22: =IFERROR(VLOOKUP(C22,Reference!$D:$E,2,0),"")
A23: 45324 | B23: 80 | C23: Utilities | D23: =IFERROR(VLOOKUP(C23,Reference!$A:$B,2,0),"") | F23: =IFERROR(VLOOKUP(C23,Reference!$D:$E,2,0),"")
A24: 45325 | B24: 120 | C24: Groceries | D24: =IFERROR(VLOOKUP(C24,Reference!$A:$B,2,0),"") | F24: =IFERROR(VLOOKUP(C24,Reference!$D:$E,2,0),"")
A25: 45327 | B25: 45 | C25: Streaming | D25: =IFERROR(VLOOKUP(C25,Reference!$A:$B,2,0),"") | F25: =IFERROR(VLOOKUP(C25,Reference!$D:$E,2,0),"")
A26: 45329 | B26: 200 | C26: Clothes | D26: =IFERROR(VLOOKUP(C26,Reference!$A:$B,2,0),"") | E26: Valentine's gift | F26: =IFERROR(VLOOKUP(C26,Reference!$D:$E,2,0),"")
A27: 45332 | B27: 75 | C27: Dining Out | D27: =IFERROR(VLOOKUP(C27,Reference!$A:$B,2,0),"") | F27: =IFERROR(VLOOKUP(C27,Reference!$D:$E,2,0),"")
A28: 45336 | B28: 500 | C28: Loan Payment | D28: =IFERROR(VLOOKUP(C28,Reference!$A:$B,2,0),"") | F28: =IFERROR(VLOOKUP(C28,Reference!$D:$E,2,0),"")
A29: 45337 | B29: 300 | C29: Savings Transfer | D29: =IFERROR(VLOOKUP(C29,Reference!$A:$B,2,0),"") | F29: =IFERROR(VLOOKUP(C29,Reference!$D:$E,2,0),"")
A30: 45340 | B30: 55 | C30: Phone | D30: =IFERROR(VLOOKUP(C30,Reference!$A:$B,2,0),"") | F30: =IFERROR(VLOOKUP(C30,Reference!$D:$E,2,0),"")
A31: 45344 | B31: 90 | C31: Gas | D31: =IFERROR(VLOOKUP(C31,Reference!$A:$B,2,0),"") | F31: =IFERROR(VLOOKUP(C31,Reference!$D:$E,2,0),"")
A32: 45352 | B32: 1200 | C32: Rent/Mortgage | D32: =IFERROR(VLOOKUP(C32,Reference!$A:$B,2,0),"") | F32: =IFERROR(VLOOKUP(C32,Reference!$D:$E,2,0),"")
A33: 45354 | B33: 95 | C33: Groceries | D33: =IFERROR(VLOOKUP(C33,Reference!$A:$B,2,0),"") | F33: =IFERROR(VLOOKUP(C33,Reference!$D:$E,2,0),"")
A34: 45356 | B34: 500 | C34: Loan Payment | D34: =IFERROR(VLOOKUP(C34,Reference!$A:$B,2,0),"") | F34: =IFERROR(VLOOKUP(C34,Reference!$D:$E,2,0),"")
A35: 45359 | B35: 60 | C35: Gym | D35: =IFERROR(VLOOKUP(C35,Reference!$A:$B,2,0),"") | F35: =IFERROR(VLOOKUP(C35,Reference!$D:$E,2,0),"")
A36: 45361 | B36: 130 | C36: Clothes | D36: =IFERROR(VLOOKUP(C36,Reference!$A:$B,2,0),"") | F36: =IFERROR(VLOOKUP(C36,Reference!$D:$E,2,0),"")
A37: 45363 | B37: 45 | C37: Streaming | D37: =IFERROR(VLOOKUP(C37,Reference!$A:$B,2,0),"") | F37: =IFERROR(VLOOKUP(C37,Reference!$D:$E,2,0),"")
A38: 45366 | B38: 250 | C38: Savings Transfer | D38: =IFERROR(VLOOKUP(C38,Reference!$A:$B,2,0),"") | F38: =IFERROR(VLOOKUP(C38,Reference!$D:$E,2,0),"")
... A41: 45376 | B41: 55 | C41: Phone | D41: =IFERROR(VLOOKUP(C41,Reference!$A:$B,2,0),"") | F41: =IFERROR(VLOOKUP(C41,Reference!$D:$E,2,0),"")
D42: =IFERROR(VLOOKUP(C42,Reference!$A:$B,2,0),"") | F42: =IFERROR(VLOOKUP(C42,Reference!$D:$E,2,0),"")
...

Sheet Reference
A1: Groceries | B1: Expenses | D1: Groceries | E1: Need | G1: January
A2: Gas | B2: Expenses | D2: Gas | E2: Need | G2: February
A3: Health | B3: Expenses | D3: Health | E3: Need | G3: March
A4: Dining Out | B4: Expenses | D4: Rent/Mortgage | E4: Need | G4: April
A5: Clothes | B5: Expenses | D5: Utilities | E5: Need | G5: May
A6: Drugstore | B6: Expenses | D6: Insurance | E6: Need | G6: June
A7: Transport | B7: Expenses | D7: Phone | E7: Need | G7: July
A8: Entertainment | B8: Expenses | D8: Internet | E8: Need | G8: August
A9: Other | B9: Expenses | D9: Dining Out | E9: Want | G9: September
A10: Rent/Mortgage | B10: Bills | D10: Clothes | E10: Want | G10: October
A11: Utilities | B11: Bills | D11: Drugstore | E11: Want | G11: November
A12: Insurance | B12: Bills | D12: Entertainment | E12: Want | G12: December
A13: Phone | B13: Bills | D13: Transport | E13: Want
A14: Internet | B14: Bills | D14: Streaming | E14: Want
A15: Streaming | B15: Subscriptions | D15: Gym | E15: Want
A16: Gym | B16: Subscriptions | D16: Other | E16: Want
A17: Loan Payment | B17: Debts | D17: Loan Payment | E17: Savings / Debts
A18: Credit Card | B18: Debts | D18: Credit Card | E18: Savings / Debts
A19: 401k | B19: Savings | D19: 401k | E19: Savings / Debts
A20: Savings Transfer | B20: Savings | D20: Savings Transfer | E20: Savings / Debts

Sheet Budget Setup
A1: INCOME & RATIO SETTINGS
A2: Monthly Income | B2: 5000
A3: Need % | B3: 50
A4: Want % | B4: 30
A5: Savings/Debts % | B5: 20
A6: Ratio Check | B6: =IF(B3+B4+B5=100,"✓ OK","⚠ Must = 100")
D8: FIXED ITEM | E8: AMOUNT | F8: CATEGORY
D9: Rent/Mortgage | E9: 1200 | F9: Bills
D10: Phone | E10: 55 | F10: Bills
D11: Internet | E11: 45 | F11: Bills
D12: Utilities | E12: 80 | F12: Bills
D13: Streaming | E13: 45 | F13: Subscriptions
D14: Gym | E14: 60 | F14: Subscriptions
D15: Loan Payment | E15: 500 | F15: Debts
